Workbook
Name Beta: '[1]Simplification>'!$C$5
Name Cost_Of_debt: '[1]Simplify using Name'!$C$9
Name Cost_Of_equity: '[1]Simplify using Name'!$C$7
Name CostofDebt: '[1]Simplification>'!$C$6
Name Current_Sales: '[1]Simplify using Name'!$G$8
Name Debt_Funding: '[1]Simplify using Name'!$C$16
Name Debt_Value: '[1]Simplify using Name'!$C$14
Name DebtValue: '[1]Simplification>'!$C$9
Name Equity_Funding: '[1]Simplify using Name'!$C$15
Name Equity_Value: '[1]Simplify using Name'!$C$13
Name EquityValue: '[1]Simplification>'!$C$8
Name Gross_Margin: '[1]Simplify using Name'!$G$10
Name MarketReturn: '[1]Simplification>'!$C$4
Name Post_Tax_Cost_of_Debt: '[1]Simplify using Name'!$C$11
Name Riskfreerate: '[1]Simplification>'!$C$3
Name Sales_Growth: '[1]Simplify using Name'!$G$9
Name Taper_rate: Sheet1!$C$22
Name Tax_rate: Sheet1!$C$27
Name TAXRate: '[1]Simplification>'!$C$7
Name UPDATE: 'Data Sheet'!$E$1

Sheet Sheet1
B2: Discounted Cashflow Model
B3: Financial Modelling Course
B6: Company Overview
B7: Reliance Industries Limited is a Fortune 500 Indian multinational conglomerate headquartered in Mumbai, Maharashtra, and led by chairman Mukesh Ambani
B8: Oil-to-Chemicals (O2C): Includes hydrocarbon exploration, petroleum refining (such as the massive Jamnagar refinery complex), and petrochemical production.
B9: Digital Services (Jio): Provides widespread telecom, 5G, and digital services that transformed India's connectivity landscape.
B10: Retail (Reliance Retail): Operates as India's largest retailer across grocery, consumer electronics, and fashion.
B11: New Energy: Focuses on green energy infrastructure, manufacturing ecosystems, and sustainable technologies.
B13: As of the 2026 financial year-end, Reliance Industries reports a total employee headcount of 4,19,911 people at the group level.
B16: Key Assumption And Methodology
B17: Parameter
B18: Valuation Date | C18: 46291
B19: Projection Period
B21: Annual Growth Tapering | C21: 0.12
C22: 0.025
B23: Terminal Growth Rate | C23: 0.06
B25: Risk Free Rate (RF) | C25: 0.0711
B26: EquityRisk Premium (ERP) | C26: 0.06
B27: Tax Rate | C27: 0.25
B30: Income Statement
B32: Particulars | C32: 44286 | D32: 44651 | E32: 45016 | F32: 45382 | G32: 45747 | H32: 46112 | I32: CAGR
B33: Sales | C33: ='Data Sheet'!F17 -> 466307 | D33: ='Data Sheet'!G17 -> 694673 | E33: ='Data Sheet'!H17 -> 876396 | F33: ='Data Sheet'!I17 -> 899041 | G33: ='Data Sheet'!J17 -> 962820 | H33: ='Data Sheet'!K17 -> 1055780
B34: % Of growth | D34: =D33/C33-1 -> 0.48973316 | E34: =E33/D33-1 -> 0.26159502 | F34: =F33/E33-1 -> 0.025838776 | G34: =G33/F33-1 -> 0.070941147 | H34: =H33/G33-1 -> 0.096549719 | I34: =_xlfn.RRI(5,C33,H33) -> 0.17755256
B35: COGS | C35: =SUM('Data Sheet'!F18,'Data Sheet'!F19,'Data Sheet'!F20:F21) -> 331730 | D35: =SUM('Data Sheet'!G18,'Data Sheet'!G19,'Data Sheet'!G20:G21) -> 545982 | E35: =SUM('Data Sheet'!H18,'Data Sheet'!H19,'Data Sheet'!H20:H21) -> 693729 | F35: =SUM('Data Sheet'!I18,'Data Sheet'!I19,'Data Sheet'!I20:I21) -> 635522 | G35: =SUM('Data Sheet'!J18,'Data Sheet'!J19,'Data Sheet'!J20:J21) -> 702118 | H35: =SUM('Data Sheet'!K18,'Data Sheet'!K19,'Data Sheet'!K20:K21) -> 752428
B36: % of Revenue | D36: =D35/C35-1 -> 0.6458626 | E36: =E35/D35-1 -> 0.27060782 | F36: =F35/E35-1 -> -0.083904522 | G36: =G35/F35-1 -> 0.10478945 | H36: =H35/G35-1 -> 0.071654622
B37: Gross Profit | C37: =C33-C35 -> 134577 | D37: =D33-D35 -> 148691 | E37: =E33-E35 -> 182667 | F37: =F33-F35 -> 263519 | G37: =G33-G35 -> 260702 | H37: =H33-H35 -> 303352
B38: % Margin | C38: =C37/C33 -> 0.28860172 | D38: =D37/D33 -> 0.21404459 | E38: =E37/E33 -> 0.20842975 | F38: =F37/F33 -> 0.29311122 | G38: =G37/G33 -> 0.2707692 | H38: =H37/H33 -> 0.28732501
B39: Operating Expenses | C39: =SUM('Data Sheet'!F22:F24) -> 71915 | D39: =SUM('Data Sheet'!G22:G24) -> 83024 | E39: =SUM('Data Sheet'!H22:H24) -> 100875 | F39: =SUM('Data Sheet'!I22:I24) -> 110787 | G39: =SUM('Data Sheet'!J22:J24) -> 125352 | H39: =SUM('Data Sheet'!K22:K24) -> 144821
B40: % Revenue | C40: =C39/C33 -> 0.15422243 | D40: =D39/D33 -> 0.11951523 | E40: =E39/E33 -> 0.11510208 | F40: =F39/F33 -> 0.12322797 | G40: =G39/G33 -> 0.13019256 | H40: =H39/H33 -> 0.13716968
B41: EBITDA | C41: =C37-C39 -> 62662 | D41: =D37-D39 -> 65667 | E41: =E37-E39 -> 81792 | F41: =F37-F39 -> 152732 | G41: =G37-G39 -> 135350 | H41: =H37-H39 -> 158531
B42: % Margin | C42: =C41/C33 -> 0.13437928 | D42: =D41/D33 -> 0.094529368 | E42: =E41/E33 -> 0.093327674 | F42: =F41/F33 -> 0.16988324 | G42: =G41/G33 -> 0.14057664 | H42: =H41/H33 -> 0.15015534
B43: Depreciation | C43: ='Data Sheet'!F26 -> 26572 | D43: ='Data Sheet'!G26 -> 29782 | E43: ='Data Sheet'!H26 -> 40303 | F43: ='Data Sheet'!I26 -> 50832 | G43: ='Data Sheet'!J26 -> 53136 | H43: ='Data Sheet'!K26 -> 57688
B44: % Of Sales | C44: =C43/C33 -> 0.056983918 | D44: =D43/D33 -> 0.04287197 | E44: =E43/E33 -> 0.045987202 | F44: =F43/F33 -> 0.056540247 | G44: =G43/G33 -> 0.055187886 | H44: =H43/H33 -> 0.054640171
B45: EBIT | C45: =C41-C43 -> 36090 | D45: =D41-D43 -> 35885 | E45: =E41-E43 -> 41489 | F45: =F41-F43 -> 101900 | G45: =G41-G43 -> 82214 | H45: =H41-H43 -> 100843
B46: % Margin | C46: =C45/C33 -> 0.077395364 | D46: =D45/D33 -> 0.051657399 | E46: =E45/E33 -> 0.047340472 | F46: =F45/F33 -> 0.113343 | G46: =G45/G33 -> 0.085388754 | H46: =H45/H33 -> 0.095515164
B47: Other Income | C47: ='Data Sheet'!F25 -> 22432 | D47: ='Data Sheet'!G25 -> 19600 | E47: ='Data Sheet'!H25 -> 12020 | F47: ='Data Sheet'!I25 -> 15792 | G47: ='Data Sheet'!J25 -> 17824 | H47: ='Data Sheet'!K25 -> 28846
B48: Interest | C48: ='Data Sheet'!F27 -> 21189 | D48: ='Data Sheet'!G27 -> 14584 | E48: ='Data Sheet'!H27 -> 19571 | F48: ='Data Sheet'!I27 -> 23118 | G48: ='Data Sheet'!J27 -> 24269 | H48: ='Data Sheet'!K27 -> 27061
B49: % debt | C49: =C48/'Data Sheet'!F59 -> 0.075956582 | D49: =D48/'Data Sheet'!G59 -> 0.045695236 | E49: =E48/'Data Sheet'!H59 -> 0.043330883 | F49: =F48/'Data Sheet'!I59 -> 0.065916018 | G49: =G48/'Data Sheet'!J59 -> 0.064836113 | H49: =H48/'Data Sheet'!K59 -> 0.067155216
B50: Profit Before Tax | C50: =C45+C47-C48 -> 37333 | D50: =D45+D47-D48 -> 40901 | E50: =E45+E47-E48 -> 33938 | F50: =F45+F47-F48 -> 94574 | G50: =G45+G47-G48 -> 75769 | H50: =H45+H47-H48 -> 102628
B51: % of Revenue | C51: =C50/C33 -> 0.08006099 | D51: =D50/D33 -> 0.058878062 | E51: =E50/E33 -> 0.038724504 | F51: =F50/F33 -> 0.10519431 | G51: =G50/G33 -> 0.078694875 | H51: =H50/H33 -> 0.097205857
...

Sheet Data Sheet
A1: COMPANY NAME | B1: RELIANCE INDUSTRIES LTD | E1: =IF(B2<>B3, "A NEW VERSION OF THE WORKSHEET IS AVAILABLE", "")
A2: LATEST VERSION | B2: 2.1 | E2: PLEASE DO NOT MAKE ANY CHANGES TO THIS SHEET
A3: CURRENT VERSION | B3: 2.1
B4: ='Data Sheet'!B1&" -" -> RELIANCE INDUSTRIES LTD -
A5: META
A6: Number of shares | B6: =IF(B9>0, B9/B8, 0) -> 1353.2535
A7: Face Value | B7: 10
A8: Current Price | B8: 1226 | C8: =IFERROR('Data Sheet'!C18,'Data Sheet'!C20:C22)*-1 -> -276076
A9: Market Capitalization | B9: 1659088.8
A15: PROFIT & LOSS
A16: Report Date | B16: 42825 | C16: 43190 | D16: 43555 | E16: 43921 | F16: 44286 | G16: 44651 | H16: 45016 | I16: 45382 | J16: 45747 | K16: 46112
A17: Sales | B17: 303954 | C17: 390823 | D17: 568337 | E17: 596679 | F17: 466307 | G17: 694673 | H17: 876396 | I17: 899041 | J17: 962820 | K17: 1055780
A18: Raw Material Cost | B18: 217518 | C18: 276076 | D18: 399167 | E18: 410288 | F18: 301765 | G18: 494449 | H18: 618746 | I18: 590226 | J18: 644813 | K18: 698930
A19: Change in Inventory | B19: 5218 | C19: 8610 | D19: 4680 | E19: 5048 | F19: 9064 | G19: 21457 | H19: 30263 | I19: 4883 | J19: 15124 | K19: 10267
A20: Power and Fuel | B20: 11251 | C20: 14569 | D20: 17029 | E20: 15098 | F20: 13214 | G20: 17902 | H20: 25062 | I20: 22137 | J20: 23823 | K20: 22069
A21: Other Mfr. Exp | B21: 9909 | C21: 9691 | D21: 12198 | E21: 11434 | F21: 7687 | G21: 12174 | H21: 19658 | I21: 18276 | J21: 18358 | K21: 21162
A22: Employee Cost | B22: 8388 | C22: 9523 | D22: 12488 | E22: 14075 | F22: 14817 | G22: 18758 | H22: 24872 | I22: 25679 | J22: 28559 | K22: 30318
A23: Selling and admin | B23: 18520 | C23: 29111 | D23: 50221 | E23: 62622 | F23: 56154 | G23: 63513 | H23: 67369 | I23: 77292 | J23: 88760 | K23: 104723
A24: Other Expenses | B24: -2721 | C24: -3852 | D24: -2336 | E24: -1056 | F24: 944 | G24: 753 | H24: 8634 | I24: 7816 | J24: 8033 | K24: 9780
A25: Other Income | B25: 9222 | C25: 9869 | D25: 8406 | E25: 8570 | F25: 22432 | G25: 19600 | H25: 12020 | I25: 15792 | J25: 17824 | K25: 28846
A26: Depreciation | B26: 11646 | C26: 16706 | D26: 20934 | E26: 22203 | F26: 26572 | G26: 29782 | H26: 40303 | I26: 50832 | J26: 53136 | K26: 57688
A27: Interest | B27: 3849 | C27: 8052 | D27: 16495 | E27: 22027 | F27: 21189 | G27: 14584 | H27: 19571 | I27: 23118 | J27: 24269 | K27: 27061
... A31: Dividend Amount | B31: 3254.9 | C31: 3553.2 | D31: 3851.9 | E31: 4120.35 | F31: 4511.5 | G31: 5412 | H31: 6089.4 | I31: 6766 | J31: 7442.6 | K31: 8119.2
A40: Quarters
A41: Report Date | B41: 45382 | C41: 45473 | D41: 45565 | E41: 45657 | F41: 45747 | G41: 45838 | H41: 45930 | I41: 46022 | J41: 46112 | K41: 46203
A42: Sales | B42: 236533 | C42: 231784 | D42: 231535 | E42: 239986 | F42: 261388 | G42: 243632 | H42: 254623 | I42: 264905 | J42: 294059 | K42: 309468
A43: Expenses | B43: 194017 | C43: 193019 | D43: 192477 | E43: 196197 | F43: 217556 | G43: 200727 | H43: 208738 | I43: 218887 | J43: 249918 | K43: 261951
A44: Other Income | B44: 4534 | C44: 3983 | D44: 4876 | E44: 4214 | F44: 4905 | G44: 15119 | H44: 4482 | I44: 4914 | J44: 4447 | K44: 6550
A45: Depreciation | B45: 13569 | C45: 13596 | D45: 12880 | E45: 13181 | F45: 13479 | G45: 13842 | H45: 14416 | I45: 14622 | J45: 14808 | K45: 15100
A46: Interest | B46: 5761 | C46: 5918 | D46: 6017 | E46: 6179 | F46: 6155 | G46: 7036 | H46: 6827 | I46: 6613 | J46: 6585 | K46: 8337
A47: Profit before tax | B47: 27720 | C47: 23234 | D47: 25037 | E47: 28643 | F47: 29103 | G47: 37146 | H47: 29124 | I47: 29697 | J47: 27195 | K47: 30630
A48: Tax | B48: 6577 | C48: 5786 | D48: 5936 | E48: 6839 | F48: 6669 | G48: 6465 | H48: 6978 | I48: 7530 | J48: 6579 | K48: 7629
A49: Net profit | B49: 18951 | C49: 15138 | D49: 16563 | E49: 18540 | F49: 19407 | G49: 26994 | H49: 18165 | I49: 18645 | J49: 16971 | K49: 20946
A50: Operating Profit | B50: 42516 | C50: 38765 | D50: 39058 | E50: 43789 | F50: 43832 | G50: 42905 | H50: 45885 | I50: 46018 | J50: 44141 | K50: 47517
A51: EBITDA | B51: 16892.02 | C51: 20164.6 | D51: 19850 | E51: 20404 | F51: 22268 | G51: 23828 | H51: 22359 | I51: 18164 | J51: 17822 | K51: 22113
A55: BALANCE SHEET
A56: Report Date | B56: 42825 | C56: 43190 | D56: 43555 | E56: 43921 | F56: 44286 | G56: 44651 | H56: 45016 | I56: 45382 | J56: 45747 | K56: 46112
A57: Equity Share Capital | B57: 2959 | C57: 5922 | D57: 5926 | E57: 6339 | F57: 6445 | G57: 6765 | H57: 6766 | I57: 6766 | J57: 13532 | K57: 13532
A58: Reserves | B58: 260750 | C58: 287584 | D58: 381186 | E58: 442827 | F58: 693727 | G58: 772720 | H58: 709106 | I58: 786715 | J58: 829668 | K58: 890498
A59: Borrowings | B59: 217475 | C59: 239843 | D59: 307714 | E59: 355133 | F59: 278962 | G59: 319158 | H59: 451664 | I59: 350719 | J59: 374313 | K59: 402962
...

Sheet Comps
B2: Comps Data
B4: Name | C4: CMP Rs. | D4: Mar Cap Rs.Cr. | E4: Debt Rs.Cr. | F4: Debt / Eq | G4: Sales Rs.Cr. | H4: Beta | I4: Cash and Equivalent
B5: Reliance Industries | C5: 1226 | D5: 1659089 | E5: 313923 | F5: 0.49 | G5: 309468 | H5: 1.15 | I5: 23196
B6: Bharti Airtel | C6: 1837 | D6: 1146380 | E6: 211854 | F6: 1.31 | G6: 58539 | H6: 0.92 | I6: 15204
B7: Indian Oil Corp (IOCL) | C7: 136 | D7: 191625 | E7: 141610 | F7: 0.81 | G7: 266407 | H7: 0.95 | I7: 12410
B8: Bharat Petroleum (BPCL) | C8: 308 | D8: 133842 | E8: 64815 | F8: 0.94 | G8: 151277 | H8: 0.89 | I8: 4213
B9: Tata Trent | C9: 2666 | D9: 142340 | E9: 684 | F9: 0.22 | G9: 4113 | H9: 1.21 | I9: 945
B12: Industry Beta
B14: Name | C14: Equit Value | D14: Total Debt | E14: Debt/Equity | F14: Debt /Capital | G14: Tax Rate % | H14: Levered Beta | I14: Unlivered Beta
B15: Reliance Industries | C15: =D5 -> 1659089 | D15: =E5 -> 313923 | E15: =D15/C15 -> 0.18921408 | F15: =D15/(C15+D15) -> 0.15910851 | G15: =Tax_rate -> 0.25 | H15: =H5 -> 1.15 | I15: =H15/(1+E15)*(1-G15) -> 0.72526891
B16: Bharti Airtel | C16: =D6 -> 1146380 | D16: =E6 -> 211854 | E16: =D16/C16 -> 0.1848026 | F16: =D16/(C16+D16) -> 0.15597754 | G16: =Tax_rate -> 0.25 | H16: =H6 -> 0.92 | I16: =H16/(1+E16)*(1-G16) -> 0.5823755
B17: Indian Oil Corp (IOCL) | C17: =D7 -> 191625 | D17: =E7 -> 141610 | E17: =D17/C17 -> 0.73899543 | F17: =D17/(C17+D17) -> 0.42495536 | G17: =Tax_rate -> 0.25 | H17: =H7 -> 0.95 | I17: =H17/(1+E17)*(1-G17) -> 0.4097193
B18: Bharat Petroleum (BPCL) | C18: =D8 -> 133842 | D18: =E8 -> 64815 | E18: =D18/C18 -> 0.48426503 | F18: =D18/(C18+D18) -> 0.32626588 | G18: =Tax_rate -> 0.25 | H18: =H8 -> 0.89 | I18: =H18/(1+E18)*(1-G18) -> 0.44971753
B19: Tata Trent | C19: =D9 -> 142340 | D19: =E9 -> 684 | E19: =D19/C19 -> 0.0048053955 | F19: =D19/(C19+D19) -> 0.0047824141 | G19: =Tax_rate -> 0.25 | H19: =H9 -> 1.21 | I19: =H19/(1+E19)*(1-G19) -> 0.90315996
B20: Average | E20: =AVERAGE(E15:E19) -> 0.32041651 | F20: =AVERAGE(F15:F19) -> 0.21421794 | G20: =AVERAGE(G15:G19) -> 0.25 | H20: =AVERAGE(H15:H19) -> 1.024 | I20: =AVERAGE(I15:I19) -> 0.61404824
B21: Median | E21: =MEDIAN(E15:E19) -> 0.18921408 | F21: =MEDIAN(F15:F19) -> 0.15910851 | G21: =MEDIAN(G15:G19) -> 0.25 | H21: =MEDIAN(H15:H19) -> 0.95 | I21: =MEDIAN(I15:I19) -> 0.5823755
